<?xml version="1.0" ?>
<!-- =================================================================================== -->
<!-- |    This document was autogenerated by xacro from rospital_moveit.urdf.xacro     | -->
<!-- |    EDITING THIS FILE BY HAND IS NOT RECOMMENDED                                 | -->
<!-- =================================================================================== -->
<robot name="rospital">
  <link name="base_footprint"/>
  <link name="base_link">
    <inertial>
      <origin rpy="0 0 0" xyz="0.00298593644358607 -0.000268295172875241 0.154640959753498"/>
      <mass value="12.0012331336924"/>
      <inertia ixx="0.35866059453322" ixy="4.67770377513155E-08" ixz="0.000423861580413772" iyy="0.233823654906046" iyz="4.66362844507336E-09" izz="0.375131573810826"/>
    </inertial>
    <visual>
      <origin rpy="0 0 0" xyz="0 0 0"/>
      <geometry>
        <mesh filename="package://rospital_description/meshes/base_link.STL"/>
      </geometry>
      <material name="">
        <color rgba="0.792156862745098 0.819607843137255 0.933333333333333 1"/>
      </material>
    </visual>
    <collision>
      <origin rpy="0 0 0" xyz="0 0 0"/>
      <geometry>
        <mesh filename="package://rospital_description/meshes/base_link.STL"/>
      </geometry>
    </collision>
  </link>
  <joint name="base_joint" type="fixed">
    <parent link="base_footprint"/>
    <child link="base_link"/>
    <origin rpy="0 0 0" xyz="0 0 0.0701"/>
  </joint>
  <link name="wheel_left_link">
    <inertial>
      <origin rpy="0 0 0" xyz="-8.64344718974191E-06 0.0228237946886783 7.57765177879927E-08"/>
      <mass value="0.778339693950675"/>
      <inertia ixx="0.00165430356623842" ixy="6.08982301451092E-09" ixz="3.56600628105672E-11" iyy="0.0030911762450513" iyz="-2.8372582055542E-11" izz="0.00165423410528579"/>
    </inertial>
    <visual>
      <origin rpy="0 0 0" xyz="0 0 0"/>
      <geometry>
        <mesh filename="package://rospital_description/meshes/wheel_left_link.STL"/>
      </geometry>
      <material name="">
        <color rgba="0.792156862745098 0.819607843137255 0.933333333333333 1"/>
      </material>
    </visual>
    <collision>
      <origin rpy="0 0 0" xyz="0 0 0"/>
      <geometry>
        <mesh filename="package://rospital_description/meshes/wheel_left_link.STL"/>
      </geometry>
    </collision>
  </link>
  <joint name="wheel_left_joint" type="continuous">
    <origin rpy="0 0 0" xyz="0 0.161 0.0154413114931434"/>
    <parent link="base_link"/>
    <child link="wheel_left_link"/>
    <axis xyz="0 1 0"/>
  </joint>
  <link name="wheel_right_link">
    <inertial>
      <origin rpy="0 0 0" xyz="8.64344718911542E-06 -0.0228237946886785 7.57765181002429E-08"/>
      <mass value="0.778339693950669"/>
      <inertia ixx="0.00165430356623842" ixy="6.08982301952646E-09" ixz="-3.56600611496615E-11" iyy="0.00309117624505131" iyz="2.83725665326271E-11" izz="0.0016542341052858"/>
    </inertial>
    <visual>
      <origin rpy="0 0 0" xyz="0 0 0"/>
      <geometry>
        <mesh filename="package://rospital_description/meshes/wheel_right_link.STL"/>
      </geometry>
      <material name="">
        <color rgba="0.792156862745098 0.819607843137255 0.933333333333333 1"/>
      </material>
    </visual>
    <collision>
      <origin rpy="0 0 0" xyz="0 0 0"/>
      <geometry>
        <mesh filename="package://rospital_description/meshes/wheel_right_link.STL"/>
      </geometry>
    </collision>
  </link>
  <joint name="wheel_right_joint" type="continuous">
    <origin rpy="0 0 0" xyz="0 -0.161 0.0154413114931451"/>
    <parent link="base_link"/>
    <child link="wheel_right_link"/>
    <axis xyz="0 1 0"/>
  </joint>
  <link name="caster_front_link">
    <inertial>
      <origin rpy="0 0 0" xyz="0.000805650652548229 5.72729797615468E-17 -4.48165838715792E-06"/>
      <mass value="0.0386238363179237"/>
      <inertia ixx="7.66294109641648E-06" ixy="-1.82721726780336E-20" ixz="2.42889623642253E-11" iyy="1.29044379500025E-05" iyz="-4.77133079419545E-24" izz="7.66293122817673E-06"/>
    </inertial>
    <visual>
      <origin rpy="0 0 0" xyz="0 0 0"/>
      <geometry>
        <mesh filename="package://rospital_description/meshes/caster_front_link.STL"/>
      </geometry>
      <material name="">
        <color rgba="0.792156862745098 0.819607843137255 0.933333333333333 1"/>
      </material>
    </visual>
    <collision>
      <origin rpy="0 0 0" xyz="0 0 0"/>
      <geometry>
        <mesh filename="package://rospital_description/meshes/caster_front_link.STL"/>
      </geometry>
    </collision>
  </link>
  <joint name="caster_front_joint" type="fixed">
    <origin rpy="0 0 0" xyz="0.229250238887004 -0.000124017376899337 -0.0431115511971616"/>
    <parent link="base_link"/>
    <child link="caster_front_link"/>
    <axis xyz="0 0 0"/>
  </joint>
  <link name="caster_rear_link">
    <inertial>
      <origin rpy="0 0 0" xyz="-0.000805650652548229 -6.01461155186334E-17 -4.48165838716486E-06"/>
      <mass value="0.0386238363179237"/>
      <inertia ixx="7.66294109641648E-06" ixy="-3.86943114962554E-20" ixz="-2.42889623642257E-11" iyy="1.29044379500025E-05" iyz="-7.32910421549178E-20" izz="7.66293122817673E-06"/>
    </inertial>
    <visual>
      <origin rpy="0 0 0" xyz="0 0 0"/>
      <geometry>
        <mesh filename="package://rospital_description/meshes/caster_rear_link.STL"/>
      </geometry>
      <material name="">
        <color rgba="0.792156862745098 0.819607843137255 0.933333333333333 1"/>
      </material>
    </visual>
    <collision>
      <origin rpy="0 0 0" xyz="0 0 0"/>
      <geometry>
        <mesh filename="package://rospital_description/meshes/caster_rear_link.STL"/>
      </geometry>
    </collision>
  </link>
  <joint name="caster_rear_joint" type="fixed">
    <origin rpy="0 0 0" xyz="-0.229157886818826 -0.000123712642857387 -0.0431115511971648"/>
    <parent link="base_link"/>
    <child link="caster_rear_link"/>
    <axis xyz="0 0 0"/>
  </joint>
  <material name="arm_grey">
    <color rgba="0.6 0.6 0.6 1"/>
  </material>
  <material name="gripper_black">
    <color rgba="0.1 0.1 0.1 1"/>
  </material>
  <joint name="left_shoulder_joint" type="revolute">
    <origin rpy="0 3.14 0" xyz="0.25 0.2 0.85"/>
    <parent link="base_link"/>
    <child link="left_upper_arm_link"/>
    <axis xyz="0 1 0"/>
    <limit effort="100" lower="-3.14" upper="0.0" velocity="1.0"/>
  </joint>
  <link name="left_upper_arm_link">
    <visual>
      <origin rpy="0 0 0" xyz="0 0 0.125"/>
      <geometry>
        <cylinder length="0.25" radius="0.04"/>
      </geometry>
      <material name="arm_grey"/>
    </visual>
    <collision>
      <origin rpy="0 0 0" xyz="0 0 0.125"/>
      <geometry>
        <cylinder length="0.25" radius="0.04"/>
      </geometry>
    </collision>
    <inertial>
      <mass value="1.0"/>
      <inertia ixx="0.01" ixy="0" ixz="0" iyy="0.01" iyz="0" izz="0.01"/>
    </inertial>
  </link>
  <joint name="left_elbow_joint" type="revolute">
    <origin rpy="0 0 0" xyz="0 0 0.25"/>
    <parent link="left_upper_arm_link"/>
    <child link="left_forearm_link"/>
    <axis xyz="1 0 0"/>
    <limit effort="100" lower="0.0" upper="1.57" velocity="1.0"/>
  </joint>
  <link name="left_forearm_link">
    <visual>
      <origin rpy="0 0 0" xyz="0 0 0.1"/>
      <geometry>
        <cylinder length="0.2" radius="0.03"/>
      </geometry>
      <material name="arm_grey"/>
    </visual>
    <collision>
      <origin rpy="0 0 0" xyz="0 0 0.1"/>
      <geometry>
        <cylinder length="0.2" radius="0.03"/>
      </geometry>
    </collision>
    <inertial>
      <mass value="0.8"/>
      <inertia ixx="0.01" ixy="0" ixz="0" iyy="0.01" iyz="0" izz="0.01"/>
    </inertial>
  </link>
  <joint name="left_wrist_joint" type="revolute">
    <origin rpy="0 0 0" xyz="0 0 0.2"/>
    <parent link="left_forearm_link"/>
    <child link="left_gripper_base_link"/>
    <axis xyz="0 0 1"/>
    <limit effort="50" lower="-1.57" upper="1.57" velocity="1.0"/>
  </joint>
  <link name="left_gripper_base_link">
    <visual>
      <origin rpy="0 0 0" xyz="0 0 0.02"/>
      <geometry>
        <box size="0.08 0.03 0.04"/>
      </geometry>
      <material name="gripper_black"/>
    </visual>
    <collision>
      <origin rpy="0 0 0" xyz="0 0 0.02"/>
      <geometry>
        <box size="0.08 0.03 0.04"/>
      </geometry>
    </collision>
    <inertial>
      <mass value="0.2"/>
      <inertia ixx="0.001" ixy="0" ixz="0" iyy="0.001" iyz="0" izz="0.001"/>
    </inertial>
  </link>
  <joint name="left_left_finger_joint" type="prismatic">
    <origin rpy="0 0 0" xyz="-0.03 0 0.04"/>
    <parent link="left_gripper_base_link"/>
    <child link="left_left_finger_link"/>
    <axis xyz="1 0 0"/>
    <limit effort="10" lower="0.0" upper="0.03" velocity="0.5"/>
  </joint>
  <link name="left_left_finger_link">
    <visual>
      <origin rpy="0 0 0" xyz="0 0 0.03"/>
      <geometry>
        <box size="0.01 0.01 0.06"/>
      </geometry>
      <material name="gripper_black"/>
    </visual>
    <collision>
      <origin rpy="0 0 0" xyz="0 0 0.03"/>
      <geometry>
        <box size="0.01 0.01 0.06"/>
      </geometry>
    </collision>
    <inertial>
      <mass value="0.05"/>
      <inertia ixx="0.0001" ixy="0" ixz="0" iyy="0.0001" iyz="0" izz="0.0001"/>
    </inertial>
  </link>
  <joint name="left_right_finger_joint" type="prismatic">
    <origin rpy="0 0 0" xyz="0.03 0 0.04"/>
    <parent link="left_gripper_base_link"/>
    <child link="left_right_finger_link"/>
    <axis xyz="-1 0 0"/>
    <limit effort="10" lower="0.0" upper="0.03" velocity="0.5"/>
  </joint>
  <link name="left_right_finger_link">
    <visual>
      <origin rpy="0 0 0" xyz="0 0 0.03"/>
      <geometry>
        <box size="0.01 0.01 0.06"/>
      </geometry>
      <material name="gripper_black"/>
    </visual>
    <collision>
      <origin rpy="0 0 0" xyz="0 0 0.03"/>
      <geometry>
        <box size="0.01 0.01 0.06"/>
      </geometry>
    </collision>
    <inertial>
      <mass value="0.05"/>
      <inertia ixx="0.0001" ixy="0" ixz="0" iyy="0.0001" iyz="0" izz="0.0001"/>
    </inertial>
  </link>
  <joint name="left_gripper_tcp_joint" type="fixed">
    <origin rpy="0 0 0" xyz="0 0 0.08"/>
    <parent link="left_gripper_base_link"/>
    <child link="left_gripper_tcp_link"/>
  </joint>
  <link name="left_gripper_tcp_link"/>
  <joint name="right_shoulder_joint" type="revolute">
    <origin rpy="0 3.14 0" xyz="0.25 -0.2 0.85"/>
    <parent link="base_link"/>
    <child link="right_upper_arm_link"/>
    <axis xyz="0 1 0"/>
    <limit effort="100" lower="-3.14" upper="0.0" velocity="1.0"/>
  </joint>
  <link name="right_upper_arm_link">
    <visual>
      <origin rpy="0 0 0" xyz="0 0 0.125"/>
      <geometry>
        <cylinder length="0.25" radius="0.04"/>
      </geometry>
      <material name="arm_grey"/>
    </visual>
    <collision>
      <origin rpy="0 0 0" xyz="0 0 0.125"/>
      <geometry>
        <cylinder length="0.25" radius="0.04"/>
      </geometry>
    </collision>
    <inertial>
      <mass value="1.0"/>
      <inertia ixx="0.01" ixy="0" ixz="0" iyy="0.01" iyz="0" izz="0.01"/>
    </inertial>
  </link>
  <joint name="right_elbow_joint" type="revolute">
    <origin rpy="0 0 0" xyz="0 0 0.25"/>
    <parent link="right_upper_arm_link"/>
    <child link="right_forearm_link"/>
    <axis xyz="1 0 0"/>
    <limit effort="100" lower="-1.57" upper="0" velocity="1.0"/>
  </joint>
  <link name="right_forearm_link">
    <visual>
      <origin rpy="0 0 0" xyz="0 0 0.1"/>
      <geometry>
        <cylinder length="0.2" radius="0.03"/>
      </geometry>
      <material name="arm_grey"/>
    </visual>
    <collision>
      <origin rpy="0 0 0" xyz="0 0 0.1"/>
      <geometry>
        <cylinder length="0.2" radius="0.03"/>
      </geometry>
    </collision>
    <inertial>
      <mass value="0.8"/>
      <inertia ixx="0.01" ixy="0" ixz="0" iyy="0.01" iyz="0" izz="0.01"/>
    </inertial>
  </link>
  <joint name="right_wrist_joint" type="revolute">
    <origin rpy="0 0 0" xyz="0 0 0.2"/>
    <parent link="right_forearm_link"/>
    <child link="right_gripper_base_link"/>
    <axis xyz="0 0 1"/>
    <limit effort="50" lower="-1.57" upper="1.57" velocity="1.0"/>
  </joint>
  <link name="right_gripper_base_link">
    <visual>
      <origin rpy="0 0 0" xyz="0 0 0.02"/>
      <geometry>
        <box size="0.08 0.03 0.04"/>
      </geometry>
      <material name="gripper_black"/>
    </visual>
    <collision>
      <origin rpy="0 0 0" xyz="0 0 0.02"/>
      <geometry>
        <box size="0.08 0.03 0.04"/>
      </geometry>
    </collision>
    <inertial>
      <mass value="0.2"/>
      <inertia ixx="0.001" ixy="0" ixz="0" iyy="0.001" iyz="0" izz="0.001"/>
    </inertial>
  </link>
  <joint name="right_left_finger_joint" type="prismatic">
    <origin rpy="0 0 0" xyz="-0.03 0 0.04"/>
    <parent link="right_gripper_base_link"/>
    <child link="right_left_finger_link"/>
    <axis xyz="1 0 0"/>
    <limit effort="10" lower="0.0" upper="0.03" velocity="0.5"/>
  </joint>
  <link name="right_left_finger_link">
    <visual>
      <origin rpy="0 0 0" xyz="0 0 0.03"/>
      <geometry>
        <box size="0.01 0.01 0.06"/>
      </geometry>
      <material name="gripper_black"/>
    </visual>
    <collision>
      <origin rpy="0 0 0" xyz="0 0 0.03"/>
      <geometry>
        <box size="0.01 0.01 0.06"/>
      </geometry>
    </collision>
    <inertial>
      <mass value="0.05"/>
      <inertia ixx="0.0001" ixy="0" ixz="0" iyy="0.0001" iyz="0" izz="0.0001"/>
    </inertial>
  </link>
  <joint name="right_right_finger_joint" type="prismatic">
    <origin rpy="0 0 0" xyz="0.03 0 0.04"/>
    <parent link="right_gripper_base_link"/>
    <child link="right_right_finger_link"/>
    <axis xyz="-1 0 0"/>
    <limit effort="10" lower="0.0" upper="0.03" velocity="0.5"/>
  </joint>
  <link name="right_right_finger_link">
    <visual>
      <origin rpy="0 0 0" xyz="0 0 0.03"/>
      <geometry>
        <box size="0.01 0.01 0.06"/>
      </geometry>
      <material name="gripper_black"/>
    </visual>
    <collision>
      <origin rpy="0 0 0" xyz="0 0 0.03"/>
      <geometry>
        <box size="0.01 0.01 0.06"/>
      </geometry>
    </collision>
    <inertial>
      <mass value="0.05"/>
      <inertia ixx="0.0001" ixy="0" ixz="0" iyy="0.0001" iyz="0" izz="0.0001"/>
    </inertial>
  </link>
  <joint name="right_gripper_tcp_joint" type="fixed">
    <origin rpy="0 0 0" xyz="0 0 0.08"/>
    <parent link="right_gripper_base_link"/>
    <child link="right_gripper_tcp_link"/>
  </joint>
  <link name="right_gripper_tcp_link"/>
  <link name="laser_link">
    <inertial>
      <origin rpy="0 0 0" xyz="-4.16811316961141E-07 -0.00020012090060817 0.0126456553172981"/>
      <mass value="0.00949435768129115"/>
      <inertia ixx="3.81407368895801E-06" ixy="-2.89093384914113E-11" ixz="2.07953967746501E-11" iyy="3.81525913149567E-06" iyz="-8.08800420939772E-10" izz="4.9344522853465E-06"/>
    </inertial>
    <visual>
      <origin rpy="0 0 0" xyz="0 0 0"/>
      <geometry>
        <mesh filename="package://rospital_description/meshes/laser_link.STL"/>
      </geometry>
      <material name="">
        <color rgba="0.0823529411764706 0.0823529411764706 0.0823529411764706 1"/>
      </material>
    </visual>
    <collision>
      <origin rpy="0 0 0" xyz="0 0 0"/>
      <geometry>
        <mesh filename="package://rospital_description/meshes/laser_link.STL"/>
      </geometry>
    </collision>
  </link>
  <joint name="laser_joint" type="fixed">
    <origin rpy="0 0 0" xyz="0.197743015846854 0.0027430158468545 0.159099867903085"/>
    <parent link="base_link"/>
    <child link="laser_link"/>
    <axis xyz="0 0 0"/>
  </joint>
  <link name="IMU_link">
    <inertial>
      <origin rpy="0 0 0" xyz="0.000281016175887924 -0.000320929221288936 0.000656651591240559"/>
      <mass value="0.000491630657107432"/>
      <inertia ixx="1.05219690062939E-08" ixy="-1.20559518329718E-10" ixz="-8.68518895699743E-11" iyy="2.60740156632658E-08" iyz="1.03040853232499E-10" izz="3.63603146259296E-08"/>
    </inertial>
    <visual>
      <origin rpy="0 0 0" xyz="0 0 0"/>
      <geometry>
        <mesh filename="package://rospital_description/meshes/IMU_link.STL"/>
      </geometry>
      <material name="">
        <color rgba="0.792156862745098 0.819607843137255 0.933333333333333 1"/>
      </material>
    </visual>
    <collision>
      <origin rpy="0 0 0" xyz="0 0 0"/>
      <geometry>
        <mesh filename="package://rospital_description/meshes/IMU_link.STL"/>
      </geometry>
    </collision>
  </link>
  <joint name="IMU_joint" type="fixed">
    <origin rpy="0 0 0" xyz="0 0 0.005"/>
    <parent link="base_link"/>
    <child link="IMU_link"/>
    <axis xyz="0 0 0"/>
  </joint>
  <link name="USB_link">
    <inertial>
      <origin rpy="0 0 0" xyz="0.00200485036829945 -6.30206112176707E-06 8.96260120698961E-05"/>
      <mass value="0.00351156143354723"/>
      <inertia ixx="2.7228430247311E-07" ixy="8.16918741171808E-14" ixz="7.23554313169072E-12" iyy="8.92094405089974E-08" iyz="-2.49782595956578E-11" izz="2.22970634830114E-07"/>
    </inertial>
    <visual>
      <origin rpy="0 0 0" xyz="0 0 0"/>
      <geometry>
        <mesh filename="package://rospital_description/meshes/USB_link.STL"/>
      </geometry>
      <material name="">
        <color rgba="0.752941176470588 0.752941176470588 0.752941176470588 1"/>
      </material>
    </visual>
    <collision>
      <origin rpy="0 0 0" xyz="0 0 0"/>
      <geometry>
        <mesh filename="package://rospital_description/meshes/USB_link.STL"/>
      </geometry>
    </collision>
  </link>
  <joint name="USB_joint" type="fixed">
    <origin rpy="0 0 -3.14" xyz="-0.297247724970268 -0.000399525317885812 0.034797072321444"/>
    <parent link="base_link"/>
    <child link="USB_link"/>
    <axis xyz="0 0 0"/>
  </joint>
  <link name="USL2_link">
    <inertial>
      <origin rpy="0 0 0" xyz="0.00200465694765273 -2.85523787015851E-05 8.96260115198499E-05"/>
      <mass value="0.00351156143354724"/>
      <inertia ixx="8.92094405089983E-08" ixy="-8.169187091625E-14" ixz="-2.49782595941744E-11" iyy="2.7228430247311E-07" iyz="-7.23554313158618E-12" izz="2.22970634830115E-07"/>
    </inertial>
    <visual>
      <origin rpy="0 0 0" xyz="0 0 0"/>
      <geometry>
        <mesh filename="package://rospital_description/meshes/USL2_link.STL"/>
      </geometry>
      <material name="">
        <color rgba="0.752941176470588 0.752941176470588 0.752941176470588 1"/>
      </material>
    </visual>
    <collision>
      <origin rpy="0 0 0" xyz="0 0 0"/>
      <geometry>
        <mesh filename="package://rospital_description/meshes/USL2_link.STL"/>
      </geometry>
    </collision>
  </link>
  <joint name="USL2_joint" type="fixed">
    <origin rpy="0 0 1.5707963267949" xyz="-0.142436694016969 0.2 0.0347970723214464"/>
    <parent link="base_link"/>
    <child link="USL2_link"/>
    <axis xyz="0 0 0"/>
  </joint>
  <link name="USL1_link">
    <inertial>
      <origin rpy="0 0 0" xyz="0.00200465694765256 -2.85523787028064E-05 8.96260115198569E-05"/>
      <mass value="0.00351156143354724"/>
      <inertia ixx="8.92094405089983E-08" ixy="-8.16918709175315E-14" ixz="-2.49782595960476E-11" iyy="2.7228430247311E-07" iyz="-7.23554313158602E-12" izz="2.22970634830115E-07"/>
    </inertial>
    <visual>
      <origin rpy="0 0 0" xyz="0 0 0"/>
      <geometry>
        <mesh filename="package://rospital_description/meshes/USL1_link.STL"/>
      </geometry>
      <material name="">
        <color rgba="0.752941176470588 0.752941176470588 0.752941176470588 1"/>
      </material>
    </visual>
    <collision>
      <origin rpy="0 0 0" xyz="0 0 0"/>
      <geometry>
        <mesh filename="package://rospital_description/meshes/USL1_link.STL"/>
      </geometry>
    </collision>
  </link>
  <joint name="USL1_joint" type="fixed">
    <origin rpy="0 0 1.5707963267949" xyz="0.141637643381198 0.2 0.0347970723214444"/>
    <parent link="base_link"/>
    <child link="USL1_link"/>
    <axis xyz="0 0 0"/>
  </joint>
  <link name="USR2_link">
    <inertial>
      <origin rpy="0 0 0" xyz="0.00200465694765181 -2.85523787021957E-05 8.9626011519732E-05"/>
      <mass value="0.00351156143354724"/>
      <inertia ixx="8.9209440508998E-08" ixy="-8.16918709225816E-14" ixz="2.4978259596054E-11" iyy="2.72284302473109E-07" iyz="7.23554313147844E-12" izz="2.22970634830113E-07"/>
    </inertial>
    <visual>
      <origin rpy="0 0 0" xyz="0 0 0"/>
      <geometry>
        <mesh filename="package://rospital_description/meshes/USR2_link.STL"/>
      </geometry>
      <material name="">
        <color rgba="0.752941176470588 0.752941176470588 0.752941176470588 1"/>
      </material>
    </visual>
    <collision>
      <origin rpy="0 0 0" xyz="0 0 0"/>
      <geometry>
        <mesh filename="package://rospital_description/meshes/USR2_link.STL"/>
      </geometry>
    </collision>
  </link>
  <joint name="USR2_joint" type="fixed">
    <origin rpy="0 0 -1.5707963267949" xyz="0.14163669401697 -0.2 0.0347970723214451"/>
    <parent link="base_link"/>
    <child link="USR2_link"/>
    <axis xyz="0 0 0"/>
  </joint>
  <link name="USR1_link">
    <inertial>
      <origin rpy="0 0 0" xyz="0.00200465694765189 -2.85523787023068E-05 8.96260115197736E-05"/>
      <mass value="0.00351156143354724"/>
      <inertia ixx="8.92094405089981E-08" ixy="-8.16918695489528E-14" ixz="2.49782595958463E-11" iyy="2.72284302473109E-07" iyz="7.23554313129476E-12" izz="2.22970634830114E-07"/>
    </inertial>
    <visual>
      <origin rpy="0 0 0" xyz="0 0 0"/>
      <geometry>
        <mesh filename="package://rospital_description/meshes/USR1_link.STL"/>
      </geometry>
      <material name="">
        <color rgba="0.752941176470588 0.752941176470588 0.752941176470588 1"/>
      </material>
    </visual>
    <collision>
      <origin rpy="0 0 0" xyz="0 0 0"/>
      <geometry>
        <mesh filename="package://rospital_description/meshes/USR1_link.STL"/>
      </geometry>
    </collision>
  </link>
  <joint name="USR1_joint" type="fixed">
    <origin rpy="0 0 -1.5707963267949" xyz="-0.142437643381199 -0.199999999999999 0.0351970723214457"/>
    <parent link="base_link"/>
    <child link="USR1_link"/>
    <axis xyz="0 0 0"/>
  </joint>
  <link name="USF_link">
    <inertial>
      <origin rpy="0 0 0" xyz="0.00200465694765267 -2.85523787022033E-05 8.96260115198708E-05"/>
      <mass value="0.00351156143354723"/>
      <inertia ixx="2.7228430247311E-07" ixy="8.16918728917237E-14" ixz="-7.23554313164944E-12" iyy="8.92094405089973E-08" iyz="2.49782595956534E-11" izz="2.22970634830114E-07"/>
    </inertial>
    <visual>
      <origin rpy="0 0 0" xyz="0 0 0"/>
      <geometry>
        <mesh filename="package://rospital_description/meshes/USF_link.STL"/>
      </geometry>
      <material name="">
        <color rgba="0.752941176470588 0.752941176470588 0.752941176470588 1"/>
      </material>
    </visual>
    <collision>
      <origin rpy="0 0 0" xyz="0 0 0"/>
      <geometry>
        <mesh filename="package://rospital_description/meshes/USF_link.STL"/>
      </geometry>
    </collision>
  </link>
  <joint name="USF_joint" type="fixed">
    <origin rpy="0 0 0" xyz="0.297247724970268 0.000399525317885919 0.0347970723214441"/>
    <parent link="base_link"/>
    <child link="USF_link"/>
    <axis xyz="0 0 0"/>
  </joint>
</robot>
